Workbook
Name ___ME1: #REF!
Name ___ME1: #REF!
Name ___ME2: #REF!
Name ___ME2: #REF!
Name ___ME3: #REF!
Name ___ME3: #REF!
Name ___ME4: #REF!
Name ___ME4: #REF!
Name ___ME5: #REF!
Name ___ME5: #REF!
Name ___ME6: #REF!
Name ___ME6: #REF!
Name ___ME7: #REF!
Name ___ME7: #REF!
Name ___ME8: #REF!
Name ___ME8: #REF!
Name __ME1: #REF!
Name __ME1: #REF!
Name __ME10: #REF!
Name __ME10: #REF!
Name __ME2: #REF!
Name __ME2: #REF!
Name __ME3: #REF!
Name __ME3: #REF!
Name __ME4: #REF!
Name __ME4: #REF!
Name __ME5: #REF!
Name __ME5: #REF!
Name __ME6: #REF!
Name __ME6: #REF!
Name __ME7: #REF!
Name __ME7: #REF!
Name __ME8: #REF!
Name __ME8: #REF!
Name _2_Dados_Gerais: #REF!
Name _2_Dados_Gerais: #REF!
Name _Area: #REF!
Name _Area: #REF!
Name _DAT1: #REF!
Name _DAT1: #REF!
Name _DAT10: #REF!
Name _DAT10: #REF!
Name _DAT11: #REF!
Name _DAT11: #REF!
Name _DAT12: #REF!
Name _DAT12: #REF!
Name _DAT13: #REF!
Name _DAT13: #REF!
Name _DAT14: #REF!
Name _DAT14: #REF!
Name _DAT15: #REF!
Name _DAT15: #REF!
Name _DAT16: #REF!
Name _DAT16: #REF!
Name _DAT17: #REF!
Name _DAT17: #REF!
Name _DAT18: #REF!
Name _DAT18: #REF!
Name _DAT19: #REF!
Name _DAT19: #REF!

Sheet PFEP
A1: Planta | B1: Semana de coleta | C1: Part Number RTM | D1: Codep Description | E1: Part Weight (Kg) | F1: Pieces- seg | G1: Pieces - ter | H1: Pieces - qua | I1: Pieces - qui | J1: Pieces - sex | K1: Pieces - sab | L1: Pieces per week | M1: Supplier Code | N1: Supplier Name | O1: Supplier City | P1: Supplier State | Q1: Supplier Country | R1: Supplier Share (%) | S1: Supplier Name + City + State | T1: Horário de Janela | U1: Original Packaging | V1: Parts per package | W1: Lenth | X1: Width | Y1: Height | Z1: Empilhavel? (S ou N) | AA1: Is the package a Tote (Yes or No) | AB1: If tote, how many packages per layer | AC1: If tote, how many layers on a pallet | AD1: Package Weight (Kg) | AE1: Restrição de Veículo | AF1: Qtd. de embalagens-Seg | AG1: Qtd. de embalagens-Ter | AH1: Qtd. de embalagens-Qua | AI1: Qtd. de embalagens-Qui | AJ1: Qtd. de embalagens-Sex | AK1: Qtd. de embalagens-Sab | AL1: Fluxo | AM1: Destino | AN1: Conta-trabalho? | AO1: Endereço Conta-trabalho | AP1: Cidade Conta-trabalho | AQ1: Estado Conta-trabalho | AR1: CDLC Destination | AS1: CNPJ Origem | AT1: CNPJ Destino | AU1: Saturação | AW1: Planta+Semana+SuppierCode+Janela | AX1: CONT.SE_ SUPPLIER | AY1: CONT_PEÇAS | AZ1: CONT_EMB | BA1: Fluxo vazio | BB1: Chave 1 | BC1: Janela
A2: FIAPE | B2: WEEK 01 | C2: 75140430 | D2: ETIQUETA AUTO-ADESIVA IDENT.NUM.CHASSI | E2: 0.001 | G2: =VLOOKUP(C2,[10]PFEP!$A:$E,5,0) -> #N/A | M2: 800006599 | N2: 3M DO BRASIL | O2: Ribeirao Preto | P2: SP | Q2: Brasil | R2: 1 | S2: 3M DO BRASIL-Ribeirao Preto-SP | T2: 0 | U2: 9906 | V2: 6000 | W2: 0.229 | X2: 0.229 | Y2: 0.152 | Z2: N | AA2: YES | AB2: 20 | AC2: 3 | AD2: 1 | AG2: =VLOOKUP(C2,[10]PFEP!$A:$AG,33,0) -> #N/A | AL2: Line Haul | AM2: FIAPE | AN2: Não | AR2: SP | AS2: 45985371003395 | AT2: 16701716003686 | AU2: Volume | AW2: =A2&B2&M2&T2&AS2&AT2&AR2&AL2 -> FIAPEWEEK 0180000659904598537100339516701716003686SPLine Haul | AX2: =COUNTIF('Suppliers DB'!AL:AL,AW2) -> 1 | AY2: =COUNT(F2:K2) -> 0 | AZ2: =COUNT(AF2:AK2) -> 0 | BA2: =IF(AL2="",0,1) -> 1 | BB2: =C2&M2 -> 75140430800006599 | BC2: =IF(AND(AL2="Milk Run",T2="_"),"Colocar Janela",0) -> 0
A3: FIAPE | B3: WEEK 01 | C3: 517226280 | D3: FITA ADESIVA NUM. CHASSI NO PAVIMENTO | E3: 0.2 | G3: =VLOOKUP(C3,[10]PFEP!$A:$E,5,0) -> 0 | M3: 800006599 | N3: 3M DO BRASIL | O3: Ribeirao Preto | P3: SP | Q3: Brasil | R3: 1 | S3: 3M DO BRASIL-Ribeirao Preto-SP | T3: 0 | U3: Papelão 3M II | V3: 40000 | W3: 0.299 | X3: 0.299 | Y3: 0.24 | Z3: S | AA3: YES | AB3: 16 | AC3: 5 | AD3: 0.5 | AG3: =VLOOKUP(C3,[10]PFEP!$A:$AG,33,0) -> 0 | AL3: Line Haul | AM3: FIAPE | AN3: Não | AR3: SP | AS3: 45985371003395 | AT3: 16701716003686 | AU3: Volume | AW3: =A3&B3&M3&T3&AS3&AT3&AR3&AL3 -> FIAPEWEEK 0180000659904598537100339516701716003686SPLine Haul | AX3: =COUNTIF('Suppliers DB'!AL:AL,AW3) -> 1 | AY3: =COUNT(F3:K3) -> 1 | AZ3: =COUNT(AF3:AK3) -> 1 | BA3: =IF(AL3="",0,1) -> 1 | BB3: =C3&M3 -> 517226280800006599 | BC3: =IF(AND(AL3="Milk Run",T3="_"),"Colocar Janela",0) -> 0
A4: FIAPE | B4: WEEK 01 | C4: 520430460 | D4: ADESIVO CENTRAL CAPO | E4: 0.08 | G4: =VLOOKUP(C4,[10]PFEP!$A:$E,5,0) -> #N/A | M4: 800006599 | N4: 3M DO BRASIL | O4: Ribeirao Preto | P4: SP | Q4: Brasil | R4: 1 | S4: 3M DO BRASIL-Ribeirao Preto-SP | T4: 0 | U4: 4203 | V4: 100 | W4: 1 | X4: 0.8 | Y4: 0.635 | Z4: S | AA4: NO | AB4: 1 | AC4: 1 | AD4: 28 | AG4: =VLOOKUP(C4,[10]PFEP!$A:$AG,33,0) -> #N/A | AL4: Line Haul | AM4: FIAPE | AN4: Não | AR4: SP | AS4: 45985371003395 | AT4: 16701716003686 | AU4: Volume | AW4: =A4&B4&M4&T4&AS4&AT4&AR4&AL4 -> FIAPEWEEK 0180000659904598537100339516701716003686SPLine Haul | AX4: =COUNTIF('Suppliers DB'!AL:AL,AW4) -> 1 | AY4: =COUNT(F4:K4) -> 0 | AZ4: =COUNT(AF4:AK4) -> 0 | BA4: =IF(AL4="",0,1) -> 1 | BB4: =C4&M4 -> 520430460800006599 | BC4: =IF(AND(AL4="Milk Run",T4="_"),"Colocar Janela",0) -> 0
A5: FIAPE | B5: WEEK 01 | C5: 520713130 | D5: PELICULA PROTETORA | E5: 0.01 | G5: =VLOOKUP(C5,[10]PFEP!$A:$E,5,0) -> #N/A | M5: 800006599 | N5: 3M DO BRASIL | O5: Ribeirao Preto | P5: SP | Q5: Brasil | R5: 1 | S5: 3M DO BRASIL-Ribeirao Preto-SP | T5: 0 | U5: 186 | V5: 5000 | W5: 0.32 | X5: 0.32 | Y5: 0.33 | Z5: N | AA5: YES | AB5: 9 | AC5: 2 | AD5: 0.5 | AG5: =VLOOKUP(C5,[10]PFEP!$A:$AG,33,0) -> #N/A | AL5: Line Haul | AM5: FIAPE | AN5: Não | AR5: SP | AS5: 45985371003395 | AT5: 16701716003686 | AU5: Volume | AW5: =A5&B5&M5&T5&AS5&AT5&AR5&AL5 -> FIAPEWEEK 0180000659904598537100339516701716003686SPLine Haul | AX5: =COUNTIF('Suppliers DB'!AL:AL,AW5) -> 1 | AY5: =COUNT(F5:K5) -> 0 | AZ5: =COUNT(AF5:AK5) -> 0 | BA5: =IF(AL5="",0,1) -> 1 | BB5: =C5&M5 -> 520713130800006599 | BC5: =IF(AND(AL5="Milk Run",T5="_"),"Colocar Janela",0) -> 0
A6: FIAPE | B6: WEEK 01 | C6: 521083900 | D6: FELTRO AUTOADESIVO | E6: 0.001 | G6: =VLOOKUP(C6,[10]PFEP!$A:$E,5,0) -> 0 | M6: 800006599 | N6: 3M DO BRASIL | O6: Ribeirao Preto | P6: SP | Q6: Brasil | R6: 1 | S6: 3M DO BRASIL-Ribeirao Preto-SP | T6: 0 | U6: Papelão 3M II | V6: 40000 | W6: 0.299 | X6: 0.299 | Y6: 0.24 | Z6: S | AA6: YES | AB6: 16 | AC6: 5 | AD6: 0.5 | AG6: =VLOOKUP(C6,[10]PFEP!$A:$AG,33,0) -> 0 | AL6: Line Haul | AM6: FIAPE | AN6: Não | AR6: SP | AS6: 45985371003395 | AT6: 16701716003686 | AU6: Volume | AW6: =A6&B6&M6&T6&AS6&AT6&AR6&AL6 -> FIAPEWEEK 0180000659904598537100339516701716003686SPLine Haul | AX6: =COUNTIF('Suppliers DB'!AL:AL,AW6) -> 1 | AY6: =COUNT(F6:K6) -> 1 | AZ6: =COUNT(AF6:AK6) -> 1 | BA6: =IF(AL6="",0,1) -> 1 | BB6: =C6&M6 -> 521083900800006599 | BC6: =IF(AND(AL6="Milk Run",T6="_"),"Colocar Janela",0) -> 0
A7: FIAPE | B7: WEEK 01 | C7: 534205810 | D7: ETIQUETA ""JEEP"" | E7: 0.01 | G7: =VLOOKUP(C7,[10]PFEP!$A:$E,5,0) -> #N/A | M7: 800006599 | N7: 3M DO BRASIL | O7: Ribeirao Preto | P7: SP | Q7: Brasil | R7: 1 | S7: 3M DO BRASIL-Ribeirao Preto-SP | T7: 0 | U7: 86 | V7: 50 | W7: 0.298 | X7: 0.198 | Y7: 0.147 | Z7: N | AA7: YES | AB7: 20 | AC7: 6 | AD7: 0.6 | AG7: =VLOOKUP(C7,[10]PFEP!$A:$AG,33,0) -> #N/A | AL7: Line Haul | AM7: FIAPE | AN7: Não | AR7: SP | AS7: 45985371003395 | AT7: 16701716003686 | AU7: Volume | AW7: =A7&B7&M7&T7&AS7&AT7&AR7&AL7 -> FIAPEWEEK 0180000659904598537100339516701716003686SPLine Haul | AX7: =COUNTIF('Suppliers DB'!AL:AL,AW7) -> 1 | AY7: =COUNT(F7:K7) -> 0 | AZ7: =COUNT(AF7:AK7) -> 0 | BA7: =IF(AL7="",0,1) -> 1 | BB7: =C7&M7 -> 534205810800006599 | BC7: =IF(AND(AL7="Milk Run",T7="_"),"Colocar Janela",0) -> 0
A8: FIAPE | B8: WEEK 01 | C8: 1002406820 | D8: FAIXA ADESIVA PORTA ANT.DX | E8: 0.05 | G8: =VLOOKUP(C8,[10]PFEP!$A:$E,5,0) -> #N/A | M8: 800006599 | N8: 3M DO BRASIL | O8: Ribeirao Preto | P8: SP | Q8: Brasil | R8: 1 | S8: 3M DO BRASIL-Ribeirao Preto-SP | T8: 0 | U8: Papelão 3M II | V8: 40000 | W8: 0.299 | X8: 0.299 | Y8: 0.24 | Z8: S | AA8: YES | AB8: 16 | AC8: 5 | AD8: 0.5 | AG8: =VLOOKUP(C8,[10]PFEP!$A:$AG,33,0) -> #N/A | AL8: Line Haul | AM8: FIAPE | AN8: Não | AR8: SP | AS8: 45985371003395 | AT8: 16701716003686 | AU8: Volume | AW8: =A8&B8&M8&T8&AS8&AT8&AR8&AL8 -> FIAPEWEEK 0180000659904598537100339516701716003686SPLine Haul | AX8: =COUNTIF('Suppliers DB'!AL:AL,AW8) -> 1 | AY8: =COUNT(F8:K8) -> 0 | AZ8: =COUNT(AF8:AK8) -> 0 | BA8: =IF(AL8="",0,1) -> 1 | BB8: =C8&M8 -> 1002406820800006599 | BC8: =IF(AND(AL8="Milk Run",T8="_"),"Colocar Janela",0) -> 0
A9: FIAPE | B9: WEEK 01 | C9: 1002406830 | D9: FAIXA ADESIVA PORTA ANT.SX | E9: 0.05 | G9: =VLOOKUP(C9,[10]PFEP!$A:$E,5,0) -> #N/A | M9: 800006599 | N9: 3M DO BRASIL | O9: Ribeirao Preto | P9: SP | Q9: Brasil | R9: 1 | S9: 3M DO BRASIL-Ribeirao Preto-SP | T9: 0 | U9: Papelão 3M II | V9: 40000 | W9: 0.299 | X9: 0.299 | Y9: 0.24 | Z9: S | AA9: YES | AB9: 16 | AC9: 5 | AD9: 0.5 | AG9: =VLOOKUP(C9,[10]PFEP!$A:$AG,33,0) -> #N/A | AL9: Line Haul | AM9: FIAPE | AN9: Não | AR9: SP | AS9: 45985371003395 | AT9: 16701716003686 | AU9: Volume | AW9: =A9&B9&M9&T9&AS9&AT9&AR9&AL9 -> FIAPEWEEK 0180000659904598537100339516701716003686SPLine Haul | AX9: =COUNTIF('Suppliers DB'!AL:AL,AW9) -> 1 | AY9: =COUNT(F9:K9) -> 0 | AZ9: =COUNT(AF9:AK9) -> 0 | BA9: =IF(AL9="",0,1) -> 1 | BB9: =C9&M9 -> 1002406830800006599 | BC9: =IF(AND(AL9="Milk Run",T9="_"),"Colocar Janela",0) -> 0
A10: FIAPE | B10: WEEK 01 | C10: 1002484070 | D10: FAIXA PORTA POSTERIOR | E10: 0.032 | G10: =VLOOKUP(C10,[10]PFEP!$A:$E,5,0) -> #N/A | M10: 800006599 | N10: 3M DO BRASIL | O10: Ribeirao Preto | P10: SP | Q10: Brasil | R10: 1 | S10: 3M DO BRASIL-Ribeirao Preto-SP | T10: 0 | U10: 156 | V10: 200 | W10: 1.35 | X10: 0.3 | Y10: 0.2 | Z10: S | AA10: YES | AB10: 3 | AC10: 4 | AD10: 0.5 | AG10: =VLOOKUP(C10,[10]PFEP!$A:$AG,33,0) -> #N/A | AL10: Line Haul | AM10: FIAPE | AN10: Não | AR10: SP | AS10: 45985371003395 | AT10: 16701716003686 | AU10: Volume | AW10: =A10&B10&M10&T10&AS10&AT10&AR10&AL10 -> FIAPEWEEK 0180000659904598537100339516701716003686SPLine Haul | AX10: =COUNTIF('Suppliers DB'!AL:AL,AW10) -> 1 | AY10: =COUNT(F10:K10) -> 0 | AZ10: =COUNT(AF10:AK10) -> 0 | BA10: =IF(AL10="",0,1) -> 1 | BB10: =C10&M10 -> 1002484070800006599 | BC10: =IF(AND(AL10="Milk Run",T10="_"),"Colocar Janela",0) -> 0
A11: FIAPE | B11: WEEK 01 | C11: 1002488510 | D11: FAIXA CAPO | E11: 0.071 | G11: =VLOOKUP(C11,[10]PFEP!$A:$E,5,0) -> #N/A | M11: 800006599 | N11: 3M DO BRASIL | O11: Ribeirao Preto | P11: SP | Q11: Brasil | R11: 1 | S11: 3M DO BRASIL-Ribeirao Preto-SP | T11: 0 | U11: 156 | V11: 200 | W11: 1.35 | X11: 0.3 | Y11: 0.2 | Z11: S | AA11: YES | AB11: 3 | AC11: 4 | AD11: 0.5 | AG11: =VLOOKUP(C11,[10]PFEP!$A:$AG,33,0) -> #N/A | AL11: Line Haul | AM11: FIAPE | AN11: Não | AR11: SP | AS11: 45985371003395 | AT11: 16701716003686 | AU11: Volume | AW11: =A11&B11&M11&T11&AS11&AT11&AR11&AL11 -> FIAPEWEEK 0180000659904598537100339516701716003686SPLine Haul | AX11: =COUNTIF('Suppliers DB'!AL:AL,AW11) -> 1 | AY11: =COUNT(F11:K11) -> 0 | AZ11: =COUNT(AF11:AK11) -> 0 | BA11: =IF(AL11="",0,1) -> 1 | BB11: =C11&M11 -> 1002488510800006599 | BC11: =IF(AND(AL11="Milk Run",T11="_"),"Colocar Janela",0) -> 0
A12: FIAPE | B12: WEEK 01 | C12: 824392160 | D12: FAIXA 30X30 | E12: 0.2 | G12: =VLOOKUP(C12,[10]PFEP!$A:$E,5,0) -> 0 | M12: 800006598 | N12: 3M DO BRASIL | O12: Sumare | P12: SP | Q12: Brasil | R12: 1 | S12: 3M DO BRASIL-Sumare-SP | T12: 0 | U12: Papelão 3M II | V12: 40000 | W12: 0.299 | X12: 0.299 | Y12: 0.24 | Z12: S | AA12: YES | AB12: 16 | AC12: 5 | AD12: 0.5 | AG12: =VLOOKUP(C12,[10]PFEP!$A:$AG,33,0) -> 0 | AL12: Line Haul | AM12: FIAPE | AN12: Não | AR12: SP | AS12: 45985371000108 | AT12: 16701716003686 | AU12: Volume | AW12: =A12&B12&M12&T12&AS12&AT12&AR12&AL12 -> FIAPEWEEK 0180000659804598537100010816701716003686SPLine Haul | AX12: =COUNTIF('Suppliers DB'!AL:AL,AW12) -> 1 | AY12: =COUNT(F12:K12) -> 1 | AZ12: =COUNT(AF12:AK12) -> 1 | BA12: =IF(AL12="",0,1) -> 1 | BB12: =C12&M12 -> 824392160800006598 | BC12: =IF(AND(AL12="Milk Run",T12="_"),"Colocar Janela",0) -> 0
A13: FIAPE | B13: WEEK 01 | C13: 76272340 | D13: PRESILHA FIX. TUBOS | E13: 0.01 | G13: =VLOOKUP(C13,[10]PFEP!$A:$E,5,0) -> 0 | M13: 800005848 | N13: A. RAYMOND | O13: Vinhedo | P13: SP | Q13: Brasil | R13: 1 | S13: A. RAYMOND-Vinhedo-SP | T13: 0.83333333 | U13: 3215 | V13: 1200 | W13: 0.3 | X13: 0.2 | Y13: 0.15 | Z13: S | AA13: YES | AB13: 20 | AC13: 3 | AD13: 1.2 | AG13: =VLOOKUP(C13,[10]PFEP!$A:$AG,33,0) -> 0 | AL13: Milk Run | AM13: FIAPE | AN13: Não | AR13: SP | AS13: 1144384000189 | AT13: 16701716003686 | AU13: Volume | AW13: =A13&B13&M13&T13&AS13&AT13&AR13&AL13 -> FIAPEWEEK 018000058480,833333333333333114438400018916701716003686SPMilk Run | AX13: =COUNTIF('Suppliers DB'!AL:AL,AW13) -> 1 | AY13: =COUNT(F13:K13) -> 1 | AZ13: =COUNT(AF13:AK13) -> 1 | BA13: =IF(AL13="",0,1) -> 1 | BB13: =C13&M13 -> 76272340800005848 | BC13: =IF(AND(AL13="Milk Run",T13="_"),"Colocar Janela",0) -> 0
A14: FIAPE | B14: WEEK 01 | C14: 76395340 | D14: PRESILHA | E14: 0.004 | G14: =VLOOKUP(C14,[10]PFEP!$A:$E,5,0) -> #N/A | M14: 800005848 | N14: A. RAYMOND | O14: Vinhedo | P14: SP | Q14: Brasil | R14: 1 | S14: A. RAYMOND-Vinhedo-SP | T14: 0.83333333 | U14: 4315 | V14: 2000 | W14: 0.4 | X14: 0.3 | Y14: 0.15 | Z14: S | AA14: YES | AB14: 9 | AC14: 3 | AD14: 1.2 | AG14: =VLOOKUP(C14,[10]PFEP!$A:$AG,33,0) -> #N/A | AL14: Milk Run | AM14: FIAPE | AN14: Não | AR14: SP | AS14: 1144384000189 | AT14: 16701716003686 | AU14: Volume | AW14: =A14&B14&M14&T14&AS14&AT14&AR14&AL14 -> FIAPEWEEK 018000058480,833333333333333114438400018916701716003686SPMilk Run | AX14: =COUNTIF('Suppliers DB'!AL:AL,AW14) -> 1 | AY14: =COUNT(F14:K14) -> 0 | AZ14: =COUNT(AF14:AK14) -> 0 | BA14: =IF(AL14="",0,1) -> 1 | BB14: =C14&M14 -> 76395340800005848 | BC14: =IF(AND(AL14="Milk Run",T14="_"),"Colocar Janela",0) -> 0
A15: FIAPE | B15: WEEK 01 | C15: 76544270 | D15: PRESILHA PLASTICA RETENCAO TUB | E15: 0.003 | G15: =VLOOKUP(C15,[10]PFEP!$A:$E,5,0) -> 0 | M15: 800005848 | N15: A. RAYMOND | O15: Vinhedo | P15: SP | Q15: Brasil | R15: 1 | S15: A. RAYMOND-Vinhedo-SP | T15: 0.83333333 | U15: 3215 | V15: 500 | W15: 0.3 | X15: 0.2 | Y15: 0.15 | Z15: S | AA15: YES | AB15: 20 | AC15: 3 | AD15: 1.2 | AG15: =VLOOKUP(C15,[10]PFEP!$A:$AG,33,0) -> 0 | AL15: Milk Run | AM15: FIAPE | AN15: Não | AR15: SP | AS15: 1144384000189 | AT15: 16701716003686 | AU15: Volume | AW15: =A15&B15&M15&T15&AS15&AT15&AR15&AL15 -> FIAPEWEEK 018000058480,833333333333333114438400018916701716003686SPMilk Run | AX15: =COUNTIF('Suppliers DB'!AL:AL,AW15) -> 1 | AY15: =COUNT(F15:K15) -> 1 | AZ15: =COUNT(AF15:AK15) -> 1 | BA15: =IF(AL15="",0,1) -> 1 | BB15: =C15&M15 -> 76544270800005848 | BC15: =IF(AND(AL15="Milk Run",T15="_"),"Colocar Janela",0) -> 0
A16: FIAPE | B16: WEEK 01 | C16: 77294240 | D16: PRESILHA P/ PARAFUSO AUTOFILETANTE D 4,8 | E16: 0.002 | G16: =VLOOKUP(C16,[10]PFEP!$A:$E,5,0) -> 2320 | M16: 800005848 | N16: A. RAYMOND | O16: Vinhedo | P16: SP | Q16: Brasil | R16: 1 | S16: A. RAYMOND-Vinhedo-SP | T16: 0.83333333 | U16: 3147 | V16: 3000 | W16: 0.3 | X16: 0.2 | Y16: 0.15 | Z16: S | AA16: YES | AB16: 20 | AC16: 3 | AD16: 0.6 | AG16: =VLOOKUP(C16,[10]PFEP!$A:$AG,33,0) -> 1 | AL16: Milk Run | AM16: FIAPE | AN16: Não | AR16: SP | AS16: 1144384000189 | AT16: 16701716003686 | AU16: Volume | AW16: =A16&B16&M16&T16&AS16&AT16&AR16&AL16 -> FIAPEWEEK 018000058480,833333333333333114438400018916701716003686SPMilk Run | AX16: =COUNTIF('Suppliers DB'!AL:AL,AW16) -> 1 | AY16: =COUNT(F16:K16) -> 1 | AZ16: =COUNT(AF16:AK16) -> 1 | BA16: =IF(AL16="",0,1) -> 1 | BB16: =C16&M16 -> 77294240800005848 | BC16: =IF(AND(AL16="Milk Run",T16="_"),"Colocar Janela",0) -> 0
A17: FIAPE | B17: WEEK 01 | C17: 77543873 | D17: BUCHA P/ PARAFUSO AUTOFILETANTE | E17: 0.001 | G17: =VLOOKUP(C17,[10]PFEP!$A:$E,5,0) -> 207026 | M17: 800005848 | N17: A. RAYMOND | O17: Vinhedo | P17: SP | Q17: Brasil | R17: 1 | S17: A. RAYMOND-Vinhedo-SP | T17: 0.83333333 | U17: 4315 | V17: 2000 | W17: 0.4 | X17: 0.3 | Y17: 0.15 | Z17: S | AA17: YES | AB17: 9 | AC17: 3 | AD17: 1.2 | AG17: =VLOOKUP(C17,[10]PFEP!$A:$AG,33,0) -> 104 | AL17: Milk Run | AM17: FIAPE | AN17: Não | AR17: SP | AS17: 1144384000189 | AT17: 16701716003686 | AU17: Volume | AW17: =A17&B17&M17&T17&AS17&AT17&AR17&AL17 -> FIAPEWEEK 018000058480,833333333333333114438400018916701716003686SPMilk Run | AX17: =COUNTIF('Suppliers DB'!AL:AL,AW17) -> 1 | AY17: =COUNT(F17:K17) -> 1 | AZ17: =COUNT(AF17:AK17) -> 1 | BA17: =IF(AL17="",0,1) -> 1 | BB17: =C17&M17 -> 77543873800005848 | BC17: =IF(AND(AL17="Milk Run",T17="_"),"Colocar Janela",0) -> 0
A18: FIAPE | B18: WEEK 01 | C18: 77701560 | D18: PORCA ESPECIAL | E18: 0.002 | G18: =VLOOKUP(C18,[10]PFEP!$A:$E,5,0) -> 11636 | M18: 800005848 | N18: A. RAYMOND | O18: Vinhedo | P18: SP | Q18: Brasil | R18: 1 | S18: A. RAYMOND-Vinhedo-SP | T18: 0.83333333 | U18: 3215 | V18: 1900 | W18: 0.3 | X18: 0.2 | Y18: 0.15 | Z18: S | AA18: YES | AB18: 20 | AC18: 3 | AD18: 1.2 | AG18: =VLOOKUP(C18,[10]PFEP!$A:$AG,33,0) -> 7 | AL18: Milk Run | AM18: FIAPE | AN18: Não | AR18: SP | AS18: 1144384000189 | AT18: 16701716003686 | AU18: Volume | AW18: =A18&B18&M18&T18&AS18&AT18&AR18&AL18 -> FIAPEWEEK 018000058480,833333333333333114438400018916701716003686SPMilk Run | AX18: =COUNTIF('Suppliers DB'!AL:AL,AW18) -> 1 | AY18: =COUNT(F18:K18) -> 1 | AZ18: =COUNT(AF18:AK18) -> 1 | BA18: =IF(AL18="",0,1) -> 1 | BB18: =C18&M18 -> 77701560800005848 | BC18: =IF(AND(AL18="Milk Run",T18="_"),"Colocar Janela",0) -> 0
A19: FIAPE | B19: WEEK 01 | C19: 468044330 | D19: PRESILHA P/FIXACAO ISOLAMENTO CAPO | E19: 0.01 | G19: =VLOOKUP(C19,[10]PFEP!$A:$E,5,0) -> 141819 | M19: 800005848 | N19: A. RAYMOND | O19: Vinhedo | P19: SP | Q19: Brasil | R19: 1 | S19: A. RAYMOND-Vinhedo-SP | T19: 0.83333333 | U19: 4315 | V19: 2000 | W19: 0.4 | X19: 0.3 | Y19: 0.15 | Z19: S | AA19: YES | AB19: 9 | AC19: 3 | AD19: 1.2 | AG19: =VLOOKUP(C19,[10]PFEP!$A:$AG,33,0) -> 48 | AL19: Milk Run | AM19: FIAPE | AN19: Não | AR19: SP | AS19: 1144384000189 | AT19: 16701716003686 | AU19: Volume | AW19: =A19&B19&M19&T19&AS19&AT19&AR19&AL19 -> FIAPEWEEK 018000058480,833333333333333114438400018916701716003686SPMilk Run | AX19: =COUNTIF('Suppliers DB'!AL:AL,AW19) -> 1 | AY19: =COUNT(F19:K19) -> 1 | AZ19: =COUNT(AF19:AK19) -> 1 | BA19: =IF(AL19="",0,1) -> 1 | BB19: =C19&M19 -> 468044330800005848 | BC19: =IF(AND(AL19="Milk Run",T19="_"),"Colocar Janela",0) -> 0
A20: FIAPE | B20: WEEK 01 | C20: 518314940 | D20: COBERTURA POLO POST. | E20: 0.013 | G20: =VLOOKUP(C20,[10]PFEP!$A:$E,5,0) -> 9373 | M20: 800005848 | N20: A. RAYMOND | O20: Vinhedo | P20: SP | Q20: Brasil | R20: 1 | S20: A. RAYMOND-Vinhedo-SP | T20: 0.83333333 | U20: 6280 | V20: 325 | W20: 0.6 | X20: 0.4 | Y20: 0.28 | Z20: S | AA20: YES | AB20: 5 | AC20: 4 | AD20: 2.67 | AG20: =VLOOKUP(C20,[10]PFEP!$A:$AG,33,0) -> 29 | AL20: Milk Run | AM20: FIAPE | AN20: Não | AR20: SP | AS20: 1144384000189 | AT20: 16701716003686 | AU20: Volume | AW20: =A20&B20&M20&T20&AS20&AT20&AR20&AL20 -> FIAPEWEEK 018000058480,833333333333333114438400018916701716003686SPMilk Run | AX20: =COUNTIF('Suppliers DB'!AL:AL,AW20) -> 1 | AY20: =COUNT(F20:K20) -> 1 | AZ20: =COUNT(AF20:AK20) -> 1 | BA20: =IF(AL20="",0,1) -> 1 | BB20: =C20&M20 -> 518314940800005848 | BC20: =IF(AND(AL20="Milk Run",T20="_"),"Colocar Janela",0) -> 0
A21: FIAPE | B21: WEEK 01 | C21: 519651510 | D21: PRESILHA FIXACAO REV. MONTANTE | E21: 0.011 | G21: =VLOOKUP(C21,[10]PFEP!$A:$E,5,0) -> 10908 | M21: 800005848 | N21: A. RAYMOND | O21: Vinhedo | P21: SP | Q21: Brasil | R21: 1 | S21: A. RAYMOND-Vinhedo-SP | T21: 0.83333333 | U21: 4280 | V21: 350 | W21: 0.395 | X21: 0.295 | Y21: 0.28 | Z21: S | AA21: YES | AB21: 10 | AC21: 4 | AD21: 2.525 | AG21: =VLOOKUP(C21,[10]PFEP!$A:$AG,33,0) -> 14 | AL21: Milk Run | AM21: FIAPE | AN21: Não | AR21: SP | AS21: 1144384000189 | AT21: 16701716003686 | AU21: Volume | AW21: =A21&B21&M21&T21&AS21&AT21&AR21&AL21 -> FIAPEWEEK 018000058480,833333333333333114438400018916701716003686SPMilk Run | AX21: =COUNTIF('Suppliers DB'!AL:AL,AW21) -> 1 | AY21: =COUNT(F21:K21) -> 1 | AZ21: =COUNT(AF21:AK21) -> 1 | BA21: =IF(AL21="",0,1) -> 1 | BB21: =C21&M21 -> 519651510800005848 | BC21: =IF(AND(AL21="Milk Run",T21="_"),"Colocar Janela",0) -> 0
A22: FIAPE | B22: WEEK 01 | C22: 520493580 | D22: BORRACHA | E22: 0.003 | G22: =VLOOKUP(C22,[10]PFEP!$A:$E,5,0) -> 20013 | M22: 800005848 | N22: A. RAYMOND | O22: Vinhedo | P22: SP | Q22: Brasil | R22: 1 | S22: A. RAYMOND-Vinhedo-SP | T22: 0.83333333 | U22: 3215 | V22: 1200 | W22: 0.3 | X22: 0.2 | Y22: 0.15 | Z22: S | AA22: YES | AB22: 20 | AC22: 3 | AD22: 1.2 | AG22: =VLOOKUP(C22,[10]PFEP!$A:$AG,33,0) -> 11 | AL22: Milk Run | AM22: FIAPE | AN22: Não | AR22: SP | AS22: 1144384000189 | AT22: 16701716003686 | AU22: Volume | AW22: =A22&B22&M22&T22&AS22&AT22&AR22&AL22 -> FIAPEWEEK 018000058480,833333333333333114438400018916701716003686SPMilk Run | AX22: =COUNTIF('Suppliers DB'!AL:AL,AW22) -> 1 | AY22: =COUNT(F22:K22) -> 1 | AZ22: =COUNT(AF22:AK22) -> 1 | BA22: =IF(AL22="",0,1) -> 1 | BB22: =C22&M22 -> 520493580800005848 | BC22: =IF(AND(AL22="Milk Run",T22="_"),"Colocar Janela",0) -> 0
A23: FIAPE | B23: WEEK 01 | C23: 522209630 | D23: PRESILHA DE RETENCAO TUBO | E23: 0.003 | G23: =VLOOKUP(C23,[10]PFEP!$A:$E,5,0) -> 4874 | M23: 800005848 | N23: A. RAYMOND | O23: Vinhedo | P23: SP | Q23: Brasil | R23: 1 | S23: A. RAYMOND-Vinhedo-SP | T23: 0.83333333 | U23: 154 | V23: 1000 | W23: 1.05 | X23: 0.66 | Y23: 0.61 | Z23: S | AA23: NO | AB23: 1 | AC23: 1 | AD23: 10 | AG23: =VLOOKUP(C23,[10]PFEP!$A:$AG,33,0) -> 5 | AL23: Milk Run | AM23: FIAPE | AN23: Não | AR23: SP | AS23: 1144384000189 | AT23: 16701716003686 | AU23: Volume | AW23: =A23&B23&M23&T23&AS23&AT23&AR23&AL23 -> FIAPEWEEK 018000058480,833333333333333114438400018916701716003686SPMilk Run | AX23: =COUNTIF('Suppliers DB'!AL:AL,AW23) -> 1 | AY23: =COUNT(F23:K23) -> 1 | AZ23: =COUNT(AF23:AK23) -> 1 | BA23: =IF(AL23="",0,1) -> 1 | BB23: =C23&M23 -> 522209630800005848 | BC23: =IF(AND(AL23="Milk Run",T23="_"),"Colocar Janela",0) -> 0
A24: FIAPE | B24: WEEK 01 | C24: 533977560 | D24: PORCA | E24: 1 | G24: =VLOOKUP(C24,[10]PFEP!$A:$E,5,0) -> 10404 | M24: 800005848 | N24: A. RAYMOND | O24: Vinhedo | P24: SP | Q24: Brasil | R24: 1 | S24: A. RAYMOND-Vinhedo-SP | T24: 0.83333333 | U24: 0 | V24: 0 | W24: 0 | X24: 0 | Y24: 0 | Z24: N | AA24: NO | AB24: 1 | AC24: 1 | AD24: 0 | AG24: =VLOOKUP(C24,[10]PFEP!$A:$AG,33,0) -> 9 | AL24: Milk Run | AM24: FIAPE | AN24: Não | AR24: SP | AS24: 1144384000189 | AT24: 16701716003686 | AU24: Volume | AW24: =A24&B24&M24&T24&AS24&AT24&AR24&AL24 -> FIAPEWEEK 018000058480,833333333333333114438400018916701716003686SPMilk Run | AX24: =COUNTIF('Suppliers DB'!AL:AL,AW24) -> 1 | AY24: =COUNT(F24:K24) -> 1 | AZ24: =COUNT(AF24:AK24) -> 1 | BA24: =IF(AL24="",0,1) -> 1 | BB24: =C24&M24 -> 533977560800005848 | BC24: =IF(AND(AL24="Milk Run",T24="_"),"Colocar Janela",0) -> 0
... A38: FIAPE | B38: WEEK 01 | C38: 521085140 | D38: FREIO A TAMBOR | E38: 4.878 | G38: =VLOOKUP(C38,[10]PFEP!$A:$E,5,0) -> 0 | M38: 800022975 | N38: AB SISTEMA | O38: Campinas | P38: SP | Q38: Brasil | R38: 1 | S38: AB SISTEMA-Campinas-SP | T38: 0.45833333 | U38: 4201 | V38: 56 | W38: 1 | X38: 1.2 | Y38: 0.86 | Z38: S | AA38: NO | AB38: 1 | AC38: 1 | AD38: 60 | AG38: =VLOOKUP(C38,[10]PFEP!$A:$AG,33,0) -> 0 | AL38: Milk Run | AM38: FIAPE | AN38: Não | AR38: SP | AS38: 13625300000108 | AT38: 16701716003686 | AU38: Volume | AW38: =A38&B38&M38&T38&AS38&AT38&AR38&AL38 -> FIAPEWEEK 018000229750,4583333333333331362530000010816701716003686SPMilk Run | AX38: =COUNTIF('Suppliers DB'!AL:AL,AW38) -> 1 | AY38: =COUNT(F38:K38) -> 1 | AZ38: =COUNT(AF38:AK38) -> 1 | BA38: =IF(AL38="",0,1) -> 1 | BB38: =C38&M38 -> 521085140800022975 | BC38: =IF(AND(AL38="Milk Run",T38="_"),"Colocar Janela",0) -> 0
A39: FIAPE | B39: WEEK 01 | C39: 520865640 | D39: FREIO A TAMBOR | E39: 5.318 | G39: =VLOOKUP(C39,[10]PFEP!$A:$E,5,0) -> 0 | M39: 800022975 | N39: AB SISTEMA | O39: Campinas | P39: SP | Q39: Brasil | R39: 1 | S39: AB SISTEMA-Campinas-SP | T39: 0.45833333 | U39: 4201 | V39: 64 | W39: 1.01 | X39: 1.2 | Y39: 0.86 | Z39: S | AA39: NO | AB39: 1 | AC39: 1 | AD39: 60 | AE39: 0 | AG39: =VLOOKUP(C39,[10]PFEP!$A:$AG,33,0) -> 0 | AL39: Milk Run | AM39: FIAPE | AN39: Não | AR39: SP | AS39: 13625300000108 | AT39: 16701716003686 | AU39: Volume | AW39: =A39&B39&M39&T39&AS39&AT39&AR39&AL39 -> FIAPEWEEK 018000229750,4583333333333331362530000010816701716003686SPMilk Run | AX39: =COUNTIF('Suppliers DB'!AL:AL,AW39) -> 1 | AY39: =COUNT(F39:K39) -> 1 | AZ39: =COUNT(AF39:AK39) -> 1 | BA39: =IF(AL39="",0,1) -> 1 | BB39: =C39&M39 -> 520865640800022975 | BC39: =IF(AND(AL39="Milk Run",T39="_"),"Colocar Janela",0) -> 0
A40: FIAPE | B40: WEEK 01 | C40: 520865670 | D40: FREIO A TAMBOR | E40: 5.318 | G40: =VLOOKUP(C40,[10]PFEP!$A:$E,5,0) -> 0 | M40: 800022975 | N40: AB SISTEMA | O40: Campinas | P40: SP | Q40: Brasil | R40: 1 | S40: AB SISTEMA-Campinas-SP | T40: 0.45833333 | U40: 4201 | V40: 64 | W40: 1.01 | X40: 1.2 | Y40: 0.86 | Z40: S | AA40: NO | AB40: 1 | AC40: 1 | AD40: 60 | AE40: 0 | AG40: =VLOOKUP(C40,[10]PFEP!$A:$AG,33,0) -> 0 | AL40: Milk Run | AM40: FIAPE | AN40: Não | AR40: SP | AS40: 13625300000108 | AT40: 16701716003686 | AU40: Volume | AW40: =A40&B40&M40&T40&AS40&AT40&AR40&AL40 -> FIAPEWEEK 018000229750,4583333333333331362530000010816701716003686SPMilk Run | AX40: =COUNTIF('Suppliers DB'!AL:AL,AW40) -> 1 | AY40: =COUNT(F40:K40) -> 1 | AZ40: =COUNT(AF40:AK40) -> 1 | BA40: =IF(AL40="",0,1) -> 1 | BB40: =C40&M40 -> 520865670800022975 | BC40: =IF(AND(AL40="Milk Run",T40="_"),"Colocar Janela",0) -> 0
A41: FIAPE | B41: WEEK 01 | C41: 463502430 | D41: DUTO DE AR | E41: 0.195 | G41: =VLOOKUP(C41,[10]PFEP!$A:$E,5,0) -> 0 | M41: 800002863 | N41: ABC GROUP | O41: Araras | P41: SP | Q41: Brasil | R41: 1 | S41: ABC GROUP-Araras-SP | T41: 0.875 | U41: 6280 | V41: 36 | W41: 0.6 | X41: 0.4 | Y41: 0.28 | Z41: S | AA41: YES | AB41: 5 | AC41: 4 | AD41: 2.67 | AG41: =VLOOKUP(C41,[10]PFEP!$A:$AG,33,0) -> 0 | AL41: Milk Run | AM41: FIAPE | AN41: Não | AR41: SP | AS41: 2679320000145 | AT41: 16701716003686 | AU41: Volume | AW41: =A41&B41&M41&T41&AS41&AT41&AR41&AL41 -> FIAPEWEEK 018000028630,875267932000014516701716003686SPMilk Run | AX41: =COUNTIF('Suppliers DB'!AL:AL,AW41) -> 1 | AY41: =COUNT(F41:K41) -> 1 | AZ41: =COUNT(AF41:AK41) -> 1 | BA41: =IF(AL41="",0,1) -> 1 | BB41: =C41&M41 -> 463502430800002863 | BC41: =IF(AND(AL41="Milk Run",T41="_"),"Colocar Janela",0) -> 0
A42: FIAPE | B42: WEEK 01 | C42: 501646620 | D42: CONDUTOR DE AR | E42: 0.025 | G42: =VLOOKUP(C42,[10]PFEP!$A:$E,5,0) -> 0 | M42: 800002863 | N42: ABC GROUP | O42: Araras | P42: SP | Q42: Brasil | R42: 1 | S42: ABC GROUP-Araras-SP | T42: 0.875 | U42: 6280 | V42: 70 | W42: 0.6 | X42: 0.4 | Y42: 0.28 | Z42: S | AA42: YES | AB42: 5 | AC42: 4 | AD42: 2.67 | AG42: =VLOOKUP(C42,[10]PFEP!$A:$AG,33,0) -> 0 | AL42: Milk Run | AM42: FIAPE | AN42: Não | AR42: SP | AS42: 2679320000145 | AT42: 16701716003686 | AU42: Peso | AW42: =A42&B42&M42&T42&AS42&AT42&AR42&AL42 -> FIAPEWEEK 018000028630,875267932000014516701716003686SPMilk Run | AX42: =COUNTIF('Suppliers DB'!AL:AL,AW42) -> 1 | AY42: =COUNT(F42:K42) -> 1 | AZ42: =COUNT(AF42:AK42) -> 1 | BA42: =IF(AL42="",0,1) -> 1 | BB42: =C42&M42 -> 501646620800002863 | BC42: =IF(AND(AL42="Milk Run",T42="_"),"Colocar Janela",0) -> 0
A43: FIAPE | B43: WEEK 01 | C43: 501646630 | D43: CONDUTOR DE AR | E43: 0.032 | G43: =VLOOKUP(C43,[10]PFEP!$A:$E,5,0) -> 0 | M43: 800002863 | N43: ABC GROUP | O43: Araras | P43: SP | Q43: Brasil | R43: 1 | S43: ABC GROUP-Araras-SP | T43: 0.875 | U43: 6280 | V43: 60 | W43: 0.6 | X43: 0.4 | Y43: 0.28 | Z43: S | AA43: YES | AB43: 5 | AC43: 4 | AD43: 2.67 | AG43: =VLOOKUP(C43,[10]PFEP!$A:$AG,33,0) -> 0 | AL43: Milk Run | AM43: FIAPE | AN43: Não | AR43: SP | AS43: 2679320000145 | AT43: 16701716003686 | AU43: Peso | AW43: =A43&B43&M43&T43&AS43&AT43&AR43&AL43 -> FIAPEWEEK 018000028630,875267932000014516701716003686SPMilk Run | AX43: =COUNTIF('Suppliers DB'!AL:AL,AW43) -> 1 | AY43: =COUNT(F43:K43) -> 1 | AZ43: =COUNT(AF43:AK43) -> 1 | BA43: =IF(AL43="",0,1) -> 1 | BB43: =C43&M43 -> 501646630800002863 | BC43: =IF(AND(AL43="Milk Run",T43="_"),"Colocar Janela",0) -> 0
A44: FIAPE | B44: WEEK 01 | C44: 501646640 | D44: CONDUTOR DE AR | E44: 0.014 | G44: =VLOOKUP(C44,[10]PFEP!$A:$E,5,0) -> 0 | M44: 800002863 | N44: ABC GROUP | O44: Araras | P44: SP | Q44: Brasil | R44: 1 | S44: ABC GROUP-Araras-SP | T44: 0.875 | U44: 6280 | V44: 150 | W44: 0.6 | X44: 0.4 | Y44: 0.28 | Z44: S | AA44: YES | AB44: 5 | AC44: 4 | AD44: 2.67 | AG44: =VLOOKUP(C44,[10]PFEP!$A:$AG,33,0) -> 0 | AL44: Milk Run | AM44: FIAPE | AN44: Não | AR44: SP | AS44: 2679320000145 | AT44: 16701716003686 | AU44: Peso | AW44: =A44&B44&M44&T44&AS44&AT44&AR44&AL44 -> FIAPEWEEK 018000028630,875267932000014516701716003686SPMilk Run | AX44: =COUNTIF('Suppliers DB'!AL:AL,AW44) -> 1 | AY44: =COUNT(F44:K44) -> 1 | AZ44: =COUNT(AF44:AK44) -> 1 | BA44: =IF(AL44="",0,1) -> 1 | BB44: =C44&M44 -> 501646640800002863 | BC44: =IF(AND(AL44="Milk Run",T44="_"),"Colocar Janela",0) -> 0
A45: FIAPE | B45: WEEK 01 | C45: 521451930 | D45: CONDUTOR DE AR DIREITO | E45: 0.45 | G45: =VLOOKUP(C45,[10]PFEP!$A:$E,5,0) -> 0 | M45: 800002863 | N45: ABC GROUP | O45: Araras | P45: SP | Q45: Brasil | R45: 1 | S45: ABC GROUP-Araras-SP | T45: 0.875 | U45: 4202 | V45: 92 | W45: 1.2 | X45: 1 | Y45: 0.86 | Z45: S | AA45: NO | AB45: 1 | AC45: 1 | AD45: 41 | AG45: =VLOOKUP(C45,[10]PFEP!$A:$AG,33,0) -> 0 | AL45: Milk Run | AM45: FIAPE | AN45: Não | AR45: SP | AS45: 2679320000145 | AT45: 16701716003686 | AU45: Volume | AW45: =A45&B45&M45&T45&AS45&AT45&AR45&AL45 -> FIAPEWEEK 018000028630,875267932000014516701716003686SPMilk Run | AX45: =COUNTIF('Suppliers DB'!AL:AL,AW45) -> 1 | AY45: =COUNT(F45:K45) -> 1 | AZ45: =COUNT(AF45:AK45) -> 1 | BA45: =IF(AL45="",0,1) -> 1 | BB45: =C45&M45 -> 521451930800002863 | BC45: =IF(AND(AL45="Milk Run",T45="_"),"Colocar Janela",0) -> 0
A46: FIAPE | B46: WEEK 01 | C46: 522194720 | D46: DUTO DE AR | E46: 0.195 | G46: =VLOOKUP(C46,[10]PFEP!$A:$E,5,0) -> 0 | M46: 800002863 | N46: ABC GROUP | O46: Araras | P46: SP | Q46: Brasil | R46: 1 | S46: ABC GROUP-Araras-SP | T46: 0.875 | U46: 6280 | V46: 36 | W46: 0.6 | X46: 0.4 | Y46: 0.28 | Z46: S | AA46: YES | AB46: 5 | AC46: 4 | AD46: 2.67 | AG46: =VLOOKUP(C46,[10]PFEP!$A:$AG,33,0) -> 0 | AL46: Milk Run | AM46: FIAPE | AN46: Não | AR46: SP | AS46: 2679320000145 | AT46: 16701716003686 | AU46: Volume | AW46: =A46&B46&M46&T46&AS46&AT46&AR46&AL46 -> FIAPEWEEK 018000028630,875267932000014516701716003686SPMilk Run | AX46: =COUNTIF('Suppliers DB'!AL:AL,AW46) -> 1 | AY46: =COUNT(F46:K46) -> 1 | AZ46: =COUNT(AF46:AK46) -> 1 | BA46: =IF(AL46="",0,1) -> 1 | BB46: =C46&M46 -> 522194720800002863 | BC46: =IF(AND(AL46="Milk Run",T46="_"),"Colocar Janela",0) -> 0
A47: FIAPE | B47: WEEK 01 | C47: 522231780 | D47: CONDUTOR DE AR | E47: 0.036 | G47: =VLOOKUP(C47,[10]PFEP!$A:$E,5,0) -> 0 | M47: 800002863 | N47: ABC GROUP | O47: Araras | P47: SP | Q47: Brasil | R47: 1 | S47: ABC GROUP-Araras-SP | T47: 0.875 | U47: 6280 | V47: 50 | W47: 0.6 | X47: 0.4 | Y47: 0.28 | Z47: S | AA47: YES | AB47: 5 | AC47: 4 | AD47: 2.67 | AG47: =VLOOKUP(C47,[10]PFEP!$A:$AG,33,0) -> 0 | AL47: Milk Run | AM47: FIAPE | AN47: Não | AR47: SP | AS47: 2679320000145 | AT47: 16701716003686 | AU47: Peso | AW47: =A47&B47&M47&T47&AS47&AT47&AR47&AL47 -> FIAPEWEEK 018000028630,875267932000014516701716003686SPMilk Run | AX47: =COUNTIF('Suppliers DB'!AL:AL,AW47) -> 1 | AY47: =COUNT(F47:K47) -> 1 | AZ47: =COUNT(AF47:AK47) -> 1 | BA47: =IF(AL47="",0,1) -> 1 | BB47: =C47&M47 -> 522231780800002863 | BC47: =IF(AND(AL47="Milk Run",T47="_"),"Colocar Janela",0) -> 0
A48: FIAPE | B48: WEEK 01 | C48: 522231790 | D48: CONDUTOR DE AR | E48: 0.017 | G48: =VLOOKUP(C48,[10]PFEP!$A:$E,5,0) -> 0 | M48: 800002863 | N48: ABC GROUP | O48: Araras | P48: SP | Q48: Brasil | R48: 1 | S48: ABC GROUP-Araras-SP | T48: 0.875 | U48: 6280 | V48: 130 | W48: 0.6 | X48: 0.4 | Y48: 0.28 | Z48: S | AA48: YES | AB48: 5 | AC48: 4 | AD48: 2.67 | AG48: =VLOOKUP(C48,[10]PFEP!$A:$AG,33,0) -> 0 | AL48: Milk Run | AM48: FIAPE | AN48: Não | AR48: SP | AS48: 2679320000145 | AT48: 16701716003686 | AU48: Peso | AW48: =A48&B48&M48&T48&AS48&AT48&AR48&AL48 -> FIAPEWEEK 018000028630,875267932000014516701716003686SPMilk Run | AX48: =COUNTIF('Suppliers DB'!AL:AL,AW48) -> 1 | AY48: =COUNT(F48:K48) -> 1 | AZ48: =COUNT(AF48:AK48) -> 1 | BA48: =IF(AL48="",0,1) -> 1 | BB48: =C48&M48 -> 522231790800002863 | BC48: =IF(AND(AL48="Milk Run",T48="_"),"Colocar Janela",0) -> 0
A49: FIAPE | B49: WEEK 01 | C49: 533632660 | D49: CONDUTOR ESQ. PAVIMENTO | E49: 0.1659 | G49: =VLOOKUP(C49,[10]PFEP!$A:$E,5,0) -> 0 | M49: 800002863 | N49: ABC GROUP | O49: Araras | P49: SP | Q49: Brasil | R49: 1 | S49: ABC GROUP-Araras-SP | T49: 0.875 | U49: 4202 | V49: 200 | W49: 1.2 | X49: 1 | Y49: 0.86 | Z49: S | AA49: NO | AB49: 1 | AC49: 1 | AD49: 41 | AG49: =VLOOKUP(C49,[10]PFEP!$A:$AG,33,0) -> 0 | AL49: Milk Run | AM49: FIAPE | AN49: Não | AR49: SP | AS49: 2679320000145 | AT49: 16701716003686 | AU49: Volume | AW49: =A49&B49&M49&T49&AS49&AT49&AR49&AL49 -> FIAPEWEEK 018000028630,875267932000014516701716003686SPMilk Run | AX49: =COUNTIF('Suppliers DB'!AL:AL,AW49) -> 1 | AY49: =COUNT(F49:K49) -> 1 | AZ49: =COUNT(AF49:AK49) -> 1 | BA49: =IF(AL49="",0,1) -> 1 | BB49: =C49&M49 -> 533632660800002863 | BC49: =IF(AND(AL49="Milk Run",T49="_"),"Colocar Janela",0) -> 0
A50: FIAPE | B50: WEEK 01 | C50: 533632670 | D50: CONDUTOR DIR. PAVIMENTO | E50: 0.1722 | G50: =VLOOKUP(C50,[10]PFEP!$A:$E,5,0) -> 0 | M50: 800002863 | N50: ABC GROUP | O50: Araras | P50: SP | Q50: Brasil | R50: 1 | S50: ABC GROUP-Araras-SP | T50: 0.875 | U50: 4202 | V50: 200 | W50: 1.2 | X50: 1 | Y50: 0.86 | Z50: S | AA50: NO | AB50: 1 | AC50: 1 | AD50: 41 | AG50: =VLOOKUP(C50,[10]PFEP!$A:$AG,33,0) -> 0 | AL50: Milk Run | AM50: FIAPE | AN50: Não | AR50: SP | AS50: 2679320000145 | AT50: 16701716003686 | AU50: Peso | AW50: =A50&B50&M50&T50&AS50&AT50&AR50&AL50 -> FIAPEWEEK 018000028630,875267932000014516701716003686SPMilk Run | AX50: =COUNTIF('Suppliers DB'!AL:AL,AW50) -> 1 | AY50: =COUNT(F50:K50) -> 1 | AZ50: =COUNT(AF50:AK50) -> 1 | BA50: =IF(AL50="",0,1) -> 1 | BB50: =C50&M50 -> 533632670800002863 | BC50: =IF(AND(AL50="Milk Run",T50="_"),"Colocar Janela",0) -> 0
A51: FIAPE | B51: WEEK 01 | C51: 533632680 | D51: CONDUTOR DE AR POST DIR | E51: 0.0546 | G51: =VLOOKUP(C51,[10]PFEP!$A:$E,5,0) -> 0 | M51: 800002863 | N51: ABC GROUP | O51: Araras | P51: SP | Q51: Brasil | R51: 1 | S51: ABC GROUP-Araras-SP | T51: 0.875 | U51: 6280 | V51: 50 | W51: 0.6 | X51: 0.4 | Y51: 0.28 | Z51: S | AA51: YES | AB51: 5 | AC51: 4 | AD51: 2.67 | AG51: =VLOOKUP(C51,[10]PFEP!$A:$AG,33,0) -> 0 | AL51: Milk Run | AM51: FIAPE | AN51: Não | AR51: SP | AS51: 2679320000145 | AT51: 16701716003686 | AU51: Volume | AW51: =A51&B51&M51&T51&AS51&AT51&AR51&AL51 -> FIAPEWEEK 018000028630,875267932000014516701716003686SPMilk Run | AX51: =COUNTIF('Suppliers DB'!AL:AL,AW51) -> 1 | AY51: =COUNT(F51:K51) -> 1 | AZ51: =COUNT(AF51:AK51) -> 1 | BA51: =IF(AL51="",0,1) -> 1 | BB51: =C51&M51 -> 533632680800002863 | BC51: =IF(AND(AL51="Milk Run",T51="_"),"Colocar Janela",0) -> 0
A52: FIAPE | B52: WEEK 01 | C52: 533632690 | D52: CONDUTOR DE AR POST DIR | E52: 0.0543 | G52: =VLOOKUP(C52,[10]PFEP!$A:$E,5,0) -> 0 | M52: 800002863 | N52: ABC GROUP | O52: Araras | P52: SP | Q52: Brasil | R52: 1 | S52: ABC GROUP-Araras-SP | T52: 0.875 | U52: 6280 | V52: 50 | W52: 0.6 | X52: 0.4 | Y52: 0.28 | Z52: S | AA52: YES | AB52: 5 | AC52: 4 | AD52: 2.67 | AG52: =VLOOKUP(C52,[10]PFEP!$A:$AG,33,0) -> 0 | AL52: Milk Run | AM52: FIAPE | AN52: Não | AR52: SP | AS52: 2679320000145 | AT52: 16701716003686 | AU52: Volume | AW52: =A52&B52&M52&T52&AS52&AT52&AR52&AL52 -> FIAPEWEEK 018000028630,875267932000014516701716003686SPMilk Run | AX52: =COUNTIF('Suppliers DB'!AL:AL,AW52) -> 1 | AY52: =COUNT(F52:K52) -> 1 | AZ52: =COUNT(AF52:AK52) -> 1 | BA52: =IF(AL52="",0,1) -> 1 | BB52: =C52&M52 -> 533632690800002863 | BC52: =IF(AND(AL52="Milk Run",T52="_"),"Colocar Janela",0) -> 0
... A55: FIAPE | B55: WEEK 01 | C55: 533261060 | D55: RESERVATORIO LIQUIDO LIMPADOR PARABRISA | E55: 0.7697 | G55: =VLOOKUP(C55,[10]PFEP!$A:$E,5,0) -> #N/A | M55: 800002863 | N55: ABC GROUP | O55: Araras | P55: SP | Q55: Brasil | R55: 1 | S55: ABC GROUP-Araras-SP | T55: 0.875 | U55: 4202 | V55: 40 | W55: 1.2 | X55: 1 | Y55: 0.86 | Z55: S | AA55: NO | AB55: 1 | AC55: 1 | AD55: 41 | AG55: =VLOOKUP(C55,[10]PFEP!$A:$AG,33,0) -> #N/A | AL55: Milk Run | AM55: FIAPE | AN55: Não | AR55: SP | AS55: 2679320000145 | AT55: 16701716003686 | AU55: Peso | AW55: =A55&B55&M55&T55&AS55&AT55&AR55&AL55 -> FIAPEWEEK 018000028630,875267932000014516701716003686SPMilk Run | AX55: =COUNTIF('Suppliers DB'!AL:AL,AW55) -> 1 | AY55: =COUNT(F55:K55) -> 0 | AZ55: =COUNT(AF55:AK55) -> 0 | BA55: =IF(AL55="",0,1) -> 1 | BB55: =C55&M55 -> 533261060800002863 | BC55: =IF(AND(AL55="Milk Run",T55="_"),"Colocar Janela",0) -> 0
...

Sheet Suppliers DB
A1: Planta | B1: Semana de coleta | C1: Supplier Code | D1: TARGET SUPPLIER + CITY | E1: Address Adjusted | F1: City | G1: State | H1: Country | I1: seg - m³ | J1: ter - m³ | K1: qua - m³ | L1: qui - m³ | M1: sex -m³ | N1: sab -m³ | O1: CDLC Destination | P1: seg - kg | Q1: ter - kg | R1: qua - kg | S1: qui - kg | T1: sex - kg | U1: sab - kg | V1: Dock Destination | W1: Milk Run | X1: Fluxo | Y1: Destino | Z1: Conta-trabalho? | AA1: Endereço Conta-trabalho | AB1: Cidade Conta-trabalho | AC1: Estado Conta-trabalho | AD1: Horário de Janela | AE1: CNPJ Origem | AF1: CNPJ Destino | AG1: Saturação | AI1: =TODAY() -> 45971 | AJ1: =WEEKDAY(AI1) -> 2 | AL1: Planta+Semana+SuppierCode+Janela | AM1: CONT.SE_ PFEP | AN1: CONT_M³ | AO1: CONT_KG | AP1: FLUXO
A2: FIAPE | B2: WEEK 01 | C2: 800006457 | D2: CLARIOS ENERGY-Sorocaba-SP | E2: Av Independencia2757eden | F2: Sorocaba | G2: SP | H2: Brasil | J2: =VLOOKUP(C2,'[10]Suppliers DB'!$A:$H,8,0) -> #N/A | O2: SP Hazmat | Q2: =VLOOKUP(C2,'[10]Suppliers DB'!$A:$O,15,0) -> #N/A | X2: Milk Run | Y2: FIAPE | Z2: Não | AD2: 0.29166667 | AE2: 1376079000112 | AF2: 16701716003686 | AG2: Peso | AL2: =A2&B2&C2&AD2&AE2&AF2&O2&X2 -> FIAPEWEEK 018000064570,291666666666667137607900011216701716003686SP HazmatMilk Run | AM2: =COUNTIF(PFEP!AW:AW,'Suppliers DB'!AL2) -> 2 | AN2: =COUNT(I2:N2) -> 0 | AO2: =COUNT(P2:U2) -> 0 | AP2: =IF(X2="",0,1) -> 1
A3: FIAPE | B3: WEEK 01 | C3: 800034219 | D3: HENKEL-Jundiai-SP | E3: Rua vice prefeito Hermenegildo | F3: Jundiai | G3: SP | H3: Brasil | J3: =VLOOKUP(C3,'[10]Suppliers DB'!$A:$H,8,0) -> 0 | O3: SP Hazmat | Q3: =VLOOKUP(C3,'[10]Suppliers DB'!$A:$O,15,0) -> 0 | X3: Milk Run | Y3: FIAPE | Z3: Não | AD3: 0.75 | AE3: 2777131003473 | AF3: 16701716003686 | AG3: Volume | AL3: =A3&B3&C3&AD3&AE3&AF3&O3&X3 -> FIAPEWEEK 018000342190,75277713100347316701716003686SP HazmatMilk Run | AM3: =COUNTIF(PFEP!AW:AW,'Suppliers DB'!AL3) -> 2 | AN3: =COUNT(I3:N3) -> 1 | AO3: =COUNT(P3:U3) -> 1 | AP3: =IF(X3="",0,1) -> 1
A4: FIAPE | B4: WEEK 01 | C4: 800039602 | D4: SIKA II-Osasco-SP | E4: Av Dr. Alberto Jackson Byington1525vila Menk | F4: Osasco | G4: SP | H4: Brasil | J4: =VLOOKUP(C4,'[10]Suppliers DB'!$A:$H,8,0) -> 0 | O4: SP Hazmat | Q4: =VLOOKUP(C4,'[10]Suppliers DB'!$A:$O,15,0) -> 0 | X4: Milk Run | Y4: FIAPE | Z4: Não | AD4: 0.66666667 | AE4: 33081704002643 | AF4: 16701716003686 | AG4: Volume | AL4: =A4&B4&C4&AD4&AE4&AF4&O4&X4 -> FIAPEWEEK 018000396020,6666666666666673308170400264316701716003686SP HazmatMilk Run | AM4: =COUNTIF(PFEP!AW:AW,'Suppliers DB'!AL4) -> 26 | AN4: =COUNT(I4:N4) -> 1 | AO4: =COUNT(P4:U4) -> 1 | AP4: =IF(X4="",0,1) -> 1
A5: FIAPE | B5: WEEK 01 | C5: 800041315 | D5: SPECIALTY-Pindamonhangaba-SP | E5: AV TOBIAS SALGADO, 345, PARQUE EMPRESARIAL SANTA RITA | F5: Pindamonhangaba | G5: SP | H5: Brasil | J5: =VLOOKUP(C5,'[10]Suppliers DB'!$A:$H,8,0) -> 0 | O5: SP Hazmat | Q5: =VLOOKUP(C5,'[10]Suppliers DB'!$A:$O,15,0) -> 0 | X5: Milk Run | Y5: FIAPE | Z5: Não | AD5: 0.58333333 | AE5: 17344766000358 | AF5: 16701716003686 | AG5: Volume | AL5: =A5&B5&C5&AD5&AE5&AF5&O5&X5 -> FIAPEWEEK 018000413150,5833333333333331734476600035816701716003686SP HazmatMilk Run | AM5: =COUNTIF(PFEP!AW:AW,'Suppliers DB'!AL5) -> 3 | AN5: =COUNT(I5:N5) -> 1 | AO5: =COUNT(P5:U5) -> 1 | AP5: =IF(X5="",0,1) -> 1
A6: FIAPE | B6: WEEK 01 | C6: 800003241 | D6: INDUSTRIAS ARTEB-São Bernardo do Campo-SP | E6: AV PIRAPORINHA 1221 | F6: São Bernardo do Campo | G6: SP | H6: Brasil | J6: =VLOOKUP(C6,'[10]Suppliers DB'!$A:$H,8,0) -> 0 | O6: SP | Q6: =VLOOKUP(C6,'[10]Suppliers DB'!$A:$O,15,0) -> 0 | X6: Milk Run | Y6: FIAPE | Z6: Não | AD6: 0.83333333 | AE6: 62291380000207 | AF6: 16701716003686 | AG6: Volume | AL6: =A6&B6&C6&AD6&AE6&AF6&O6&X6 -> FIAPEWEEK 018000032410,8333333333333336229138000020716701716003686SPMilk Run | AM6: =COUNTIF(PFEP!AW:AW,'Suppliers DB'!AL6) -> 15 | AN6: =COUNT(I6:N6) -> 1 | AO6: =COUNT(P6:U6) -> 1 | AP6: =IF(X6="",0,1) -> 1
A7: FIAPE | B7: WEEK 01 | C7: 800046299 | D7: MAGNA-São Bernardo do Campo-SP | E7: Av Alvaro Guimaraes 1100, sala | F7: São Bernardo do Campo | G7: SP | H7: Brasil | J7: =VLOOKUP(C7,'[10]Suppliers DB'!$A:$H,8,0) -> 0 | O7: SP | Q7: =VLOOKUP(C7,'[10]Suppliers DB'!$A:$O,15,0) -> 0 | X7: Milk Run | Y7: FIAPE | Z7: Não | AD7: 0.875 | AE7: 3479456000174 | AF7: 16701716003686 | AG7: Volume | AL7: =A7&B7&C7&AD7&AE7&AF7&O7&X7 -> FIAPEWEEK 018000462990,875347945600017416701716003686SPMilk Run | AM7: =COUNTIF(PFEP!AW:AW,'Suppliers DB'!AL7) -> 13 | AN7: =COUNT(I7:N7) -> 1 | AO7: =COUNT(P7:U7) -> 1 | AP7: =IF(X7="",0,1) -> 1
A8: FIAPE | B8: WEEK 01 | C8: 800006599 | D8: 3M DO BRASIL-Ribeirao Preto-SP | E8: Rdv Rib Preto Araraquara7kmbonfim Paulista | F8: Ribeirao Preto | G8: SP | H8: Brasil | J8: =VLOOKUP(C8,'[10]Suppliers DB'!$A:$H,8,0) -> 0 | O8: SP | Q8: =VLOOKUP(C8,'[10]Suppliers DB'!$A:$O,15,0) -> 0 | X8: Line Haul | Y8: FIAPE | Z8: Não | AD8: 0 | AE8: =VLOOKUP(C8,PFEP!M:AS,33,0) -> 45985371003395 | AF8: 16701716003686 | AG8: Volume | AL8: =A8&B8&C8&AD8&AE8&AF8&O8&X8 -> FIAPEWEEK 0180000659904598537100339516701716003686SPLine Haul | AM8: =COUNTIF(PFEP!AW:AW,'Suppliers DB'!AL8) -> 10 | AN8: =COUNT(I8:N8) -> 1 | AO8: =COUNT(P8:U8) -> 1 | AP8: =IF(X8="",0,1) -> 1
A9: FIAPE | B9: WEEK 01 | C9: 800006598 | D9: 3M DO BRASIL-Sumare-SP | E9: Rdv Anhangueira Km110snjardim Manchester Nova Vene | F9: Sumare | G9: SP | H9: Brasil | J9: =VLOOKUP(C9,'[10]Suppliers DB'!$A:$H,8,0) -> 0 | O9: SP | Q9: =VLOOKUP(C9,'[10]Suppliers DB'!$A:$O,15,0) -> 0 | X9: Line Haul | Y9: FIAPE | Z9: Não | AD9: 0 | AE9: 45985371000108 | AF9: 16701716003686 | AG9: Volume | AL9: =A9&B9&C9&AD9&AE9&AF9&O9&X9 -> FIAPEWEEK 0180000659804598537100010816701716003686SPLine Haul | AM9: =COUNTIF(PFEP!AW:AW,'Suppliers DB'!AL9) -> 1 | AN9: =COUNT(I9:N9) -> 1 | AO9: =COUNT(P9:U9) -> 1 | AP9: =IF(X9="",0,1) -> 1
A10: FIAPE | B10: WEEK 01 | C10: 800005870 | D10: NIDEC MOBILIDAD-Viinhedo-SP | E10: FRANCISCO FOGA 980 | F10: Viinhedo | G10: SP | H10: Brasil | J10: =VLOOKUP(C10,'[10]Suppliers DB'!$A:$H,8,0) -> 0 | O10: SP | Q10: =VLOOKUP(C10,'[10]Suppliers DB'!$A:$O,15,0) -> 0 | X10: Line Haul | Y10: FIAPE | Z10: Não | AD10: 0 | AE10: 7760479000103 | AF10: 16701716003686 | AG10: Volume | AL10: =A10&B10&C10&AD10&AE10&AF10&O10&X10 -> FIAPEWEEK 018000058700776047900010316701716003686SPLine Haul | AM10: =COUNTIF(PFEP!AW:AW,'Suppliers DB'!AL10) -> 3 | AN10: =COUNT(I10:N10) -> 1 | AO10: =COUNT(P10:U10) -> 1 | AP10: =IF(X10="",0,1) -> 1
A11: FIAPE | B11: WEEK 01 | C11: 800027166 | D11: TESA BRASIL-Curitiba-PR | E11: Av. Joao Gualberto1259cj. 1801/2alto Da Gloria | F11: Curitiba | G11: PR | H11: Brasil | J11: =VLOOKUP(C11,'[10]Suppliers DB'!$A:$H,8,0) -> 0 | O11: SP | Q11: =VLOOKUP(C11,'[10]Suppliers DB'!$A:$O,15,0) -> 0 | X11: Line Haul | Y11: FIAPE | Z11: Não | AD11: 0 | AE11: 4480645000120 | AF11: 16701716003686 | AG11: Peso | AL11: =A11&B11&C11&AD11&AE11&AF11&O11&X11 -> FIAPEWEEK 018000271660448064500012016701716003686SPLine Haul | AM11: =COUNTIF(PFEP!AW:AW,'Suppliers DB'!AL11) -> 24 | AN11: =COUNT(I11:N11) -> 1 | AO11: =COUNT(P11:U11) -> 1 | AP11: =IF(X11="",0,1) -> 1
A12: FIAPE | B12: WEEK 01 | C12: 800046527 | D12: BASF CATALISADORES-Indaiatuba-SP | E12: Indaiatuba | F12: Indaiatuba | G12: SP | H12: Brasil | J12: =VLOOKUP(C12,'[10]Suppliers DB'!$A:$H,8,0) -> 0 | O12: SP | Q12: =VLOOKUP(C12,'[10]Suppliers DB'!$A:$O,15,0) -> 0 | X12: Milk Run | Y12: FIAPE | Z12: Não | AD12: 0.33333333 | AE12: 48439341000194 | AF12: 16701716003686 | AG12: Volume | AL12: =A12&B12&C12&AD12&AE12&AF12&O12&X12 -> FIAPEWEEK 018000465270,3333333333333334843934100019416701716003686SPMilk Run | AM12: =COUNTIF(PFEP!AW:AW,'Suppliers DB'!AL12) -> 0 | AN12: =COUNT(I12:N12) -> 1 | AO12: =COUNT(P12:U12) -> 1 | AP12: =IF(X12="",0,1) -> 1
A13: FIAPE | B13: WEEK 01 | C13: 800022239 | D13: GIOBERT DO BRASIL SIST. AUTOMOTIVOS-Jaguariuna-SP | E13: VICENZO GRANGHELLI 856, GP 04 | F13: Jaguariuna | G13: SP | H13: Brasil | J13: =VLOOKUP(C13,'[10]Suppliers DB'!$A:$H,8,0) -> 0.2364 | O13: SP | Q13: =VLOOKUP(C13,'[10]Suppliers DB'!$A:$O,15,0) -> 109.56 | X13: Line Haul | Y13: FIAPE | Z13: Não | AE13: 13258571000172 | AF13: 16701716003686 | AG13: Volume | AL13: =A13&B13&C13&AD13&AE13&AF13&O13&X13 -> FIAPEWEEK 018000222391325857100017216701716003686SPLine Haul | AM13: =COUNTIF(PFEP!AW:AW,'Suppliers DB'!AL111) -> 8 | AN13: =COUNT(I13:N13) -> 1 | AO13: =COUNT(P13:U13) -> 1 | AP13: =IF(X13="",0,1) -> 1
A14: FIAPE | B14: WEEK 01 | C14: 800022975 | D14: AB SISTEMA-Campinas-SP | E14: Rua Joao Felipe Xavier Da Silva384sao Bernardo | F14: Campinas | G14: SP | H14: Brasil | J14: =VLOOKUP(C14,'[10]Suppliers DB'!$A:$H,8,0) -> 0 | O14: SP | Q14: =VLOOKUP(C14,'[10]Suppliers DB'!$A:$O,15,0) -> 0 | X14: Milk Run | Y14: FIAPE | Z14: Não | AD14: 0.45833333 | AE14: 13625300000108 | AF14: 16701716003686 | AG14: Volume | AL14: =A14&B14&C14&AD14&AE14&AF14&O14&X14 -> FIAPEWEEK 018000229750,4583333333333331362530000010816701716003686SPMilk Run | AM14: =COUNTIF(PFEP!AW:AW,'Suppliers DB'!AL14) -> 8 | AN14: =COUNT(I14:N14) -> 1 | AO14: =COUNT(P14:U14) -> 1 | AP14: =IF(X14="",0,1) -> 1
A15: FIAPE | B15: WEEK 01 | C15: 800002863 | D15: ABC GROUP-Araras-SP | E15: R. José Carrocci, 555 - Distrito Industrial I - 13602-030 | F15: Araras | G15: SP | H15: Brasil | J15: =VLOOKUP(C15,'[10]Suppliers DB'!$A:$H,8,0) -> 0 | O15: SP | Q15: =VLOOKUP(C15,'[10]Suppliers DB'!$A:$O,15,0) -> 0 | X15: Milk Run | Y15: FIAPE | Z15: Não | AD15: 0.875 | AE15: 2679320000145 | AF15: 16701716003686 | AG15: Peso | AL15: =A15&B15&C15&AD15&AE15&AF15&O15&X15 -> FIAPEWEEK 018000028630,875267932000014516701716003686SPMilk Run | AM15: =COUNTIF(PFEP!AW:AW,'Suppliers DB'!AL15) -> 15 | AN15: =COUNT(I15:N15) -> 1 | AO15: =COUNT(P15:U15) -> 1 | AP15: =IF(X15="",0,1) -> 1
A16: FIAPE | B16: WEEK 01 | C16: 800009856 | D16: ALPINO IND META-Jundiai-SP | E16: Av Juvenal Arantes313jardim Carolina | F16: Jundiai | G16: SP | H16: Brasil | J16: =VLOOKUP(C16,'[10]Suppliers DB'!$A:$H,8,0) -> 0 | O16: SP | Q16: =VLOOKUP(C16,'[10]Suppliers DB'!$A:$O,15,0) -> 0 | W16: Não recebe veículo Baú | X16: Milk Run | Y16: FIAPE | Z16: Não | AD16: 0.91666667 | AE16: 61451027000195 | AF16: 16701716003686 | AG16: Volume | AL16: =A16&B16&C16&AD16&AE16&AF16&O16&X16 -> FIAPEWEEK 018000098560,9166666666666676145102700019516701716003686SPMilk Run | AM16: =COUNTIF(PFEP!AW:AW,'Suppliers DB'!AL16) -> 5 | AN16: =COUNT(I16:N16) -> 1 | AO16: =COUNT(P16:U16) -> 1 | AP16: =IF(X16="",0,1) -> 1
A17: FIAPE | B17: WEEK 01 | C17: 800005810 | D17: APTIV-Jambeiro-SP | E17: Rdv Dos Tamoios km 21 | F17: #N/A | G17: SP | H17: Brasil | J17: =VLOOKUP(C17,'[10]Suppliers DB'!$A:$H,8,0) -> #N/A | O17: SP | Q17: =VLOOKUP(C17,'[10]Suppliers DB'!$A:$O,15,0) -> #N/A | X17: Milk Run | Y17: FIAPE | Z17: Não | AD17: 0.625 | AE17: 857758000736 | AF17: 16701716003686 | AG17: Volume | AL17: =A17&B17&C17&AD17&AE17&AF17&O17&X17 -> FIAPEWEEK 018000058100,62585775800073616701716003686SPMilk Run | AM17: =COUNTIF(PFEP!AW:AW,'Suppliers DB'!AL17) -> 3 | AN17: =COUNT(I17:N17) -> 0 | AO17: =COUNT(P17:U17) -> 0 | AP17: =IF(X17="",0,1) -> 1
A18: FIAPE | B18: WEEK 01 | C18: 800036277 | D18: AUTO PARTS-Tatui-SP | E18: AVENIDA DOS AERONAUTAS 1015, JARDIM AEROPORTO | F18: Tatui | G18: SP | H18: Brasil | J18: =VLOOKUP(C18,'[10]Suppliers DB'!$A:$H,8,0) -> 0 | O18: SP | Q18: =VLOOKUP(C18,'[10]Suppliers DB'!$A:$O,15,0) -> 0 | X18: Milk Run | Y18: FIAPE | Z18: Não | AD18: 0.91666667 | AE18: 22066976000280 | AF18: 16701716003686 | AG18: Volume | AL18: =A18&B18&C18&AD18&AE18&AF18&O18&X18 -> FIAPEWEEK 018000362770,9166666666666672206697600028016701716003686SPMilk Run | AM18: =COUNTIF(PFEP!AW:AW,'Suppliers DB'!AL18) -> 5 | AN18: =COUNT(I18:N18) -> 1 | AO18: =COUNT(P18:U18) -> 1 | AP18: =IF(X18="",0,1) -> 1
A19: FIAPE | B19: WEEK 01 | C19: 800006157 | D19: AUTOMETAL-Sao Bernardo Do Campo-SP | E19: Estrada Eiji Kikuti, 300, GALPAO 2, Cooperativa | F19: #N/A | G19: SP | H19: Brasil | J19: =VLOOKUP(C19,'[10]Suppliers DB'!$A:$H,8,0) -> #N/A | O19: SP | Q19: =VLOOKUP(C19,'[10]Suppliers DB'!$A:$O,15,0) -> #N/A | W19: Não recebe carreta | X19: Milk Run | Y19: FIAPE | Z19: Não | AD19: 0.625 | AE19: 3985506000195 | AF19: 16701716003686 | AG19: Volume | AL19: =A19&B19&C19&AD19&AE19&AF19&O19&X19 -> FIAPEWEEK 018000061570,625398550600019516701716003686SPMilk Run | AM19: =COUNTIF(PFEP!AW:AW,'Suppliers DB'!AL19) -> 7 | AN19: =COUNT(I19:N19) -> 0 | AO19: =COUNT(P19:U19) -> 0 | AP19: =IF(X19="",0,1) -> 1
A20: FIAPE | B20: WEEK 01 | C20: 800027551 | D20: BASF-Guarulhos-SP | E20: Estrada Municipal1156a / D,ejardim Santo Afonso | F20: Guarulhos | G20: SP | H20: Brasil | J20: =VLOOKUP(C20,'[10]Suppliers DB'!$A:$H,8,0) -> 0 | O20: SP | Q20: =VLOOKUP(C20,'[10]Suppliers DB'!$A:$O,15,0) -> 0 | X20: Milk Run | Y20: FIAPE | Z20: Não | AD20: 0.625 | AE20: 48539407009174 | AF20: 16701716003686 | AG20: Volume | AL20: =A20&B20&C20&AD20&AE20&AF20&O20&X20 -> FIAPEWEEK 018000275510,6254853940700917416701716003686SPMilk Run | AM20: =COUNTIF(PFEP!AW:AW,'Suppliers DB'!AL20) -> 17 | AN20: =COUNT(I20:N20) -> 1 | AO20: =COUNT(P20:U20) -> 1 | AP20: =IF(X20="",0,1) -> 1
A21: FIAPE | B21: WEEK 01 | C21: 800008407 | D21: BASF-Indaiatuba-SP | E21: Rdv Sp 735756caldeira | F21: Indaiatuba | G21: SP | H21: Brasil | J21: =VLOOKUP(C21,'[10]Suppliers DB'!$A:$H,8,0) -> 0 | O21: SP | Q21: =VLOOKUP(C21,'[10]Suppliers DB'!$A:$O,15,0) -> 0 | W21: Não recebe carreta | Apenas Veículos do tipo Sider | X21: Milk Run | Y21: FIAPE | Z21: Não | AD21: 0.58333333 | AE21: 48539407002919 | AF21: 16701716003686 | AG21: Volume | AL21: =A21&B21&C21&AD21&AE21&AF21&O21&X21 -> FIAPEWEEK 018000084070,5833333333333334853940700291916701716003686SPMilk Run | AM21: =COUNTIF(PFEP!AW:AW,'Suppliers DB'!AL21) -> 1 | AN21: =COUNT(I21:N21) -> 1 | AO21: =COUNT(P21:U21) -> 1 | AP21: =IF(X21="",0,1) -> 1
A22: FIAPE | B22: WEEK 01 | C22: 800028796a | D22: BENTELER MR-Campinas-SP | E22: Marginal Sul802km 69distrito Industrial | F22: Campinas | G22: SP | H22: Brasil | J22: =VLOOKUP(C22,'[10]Suppliers DB'!$A:$H,8,0) -> 0 | O22: SP | Q22: =VLOOKUP(C22,'[10]Suppliers DB'!$A:$O,15,0) -> 0 | X22: Milk Run | Y22: FIAPE | Z22: Não | AD22: 0.875 | AE22: 853157000160 | AF22: 16701716003686 | AG22: Volume | AL22: =A22&B22&C22&AD22&AE22&AF22&O22&X22 -> FIAPEWEEK 01800028796a0,87585315700016016701716003686SPMilk Run | AM22: =COUNTIF(PFEP!AW:AW,'Suppliers DB'!AL22) -> 4 | AN22: =COUNT(I22:N22) -> 1 | AO22: =COUNT(P22:U22) -> 1 | AP22: =IF(X22="",0,1) -> 1
A23: FIAPE | B23: WEEK 01 | C23: 800006653 | D23: BOLLHOFF SERVICE-Jundiai-SP | E23: Av Arquimedes500dist. Industrial | F23: Jundiai | G23: SP | H23: Brasil | J23: =VLOOKUP(C23,'[10]Suppliers DB'!$A:$H,8,0) -> 0 | O23: SP | Q23: =VLOOKUP(C23,'[10]Suppliers DB'!$A:$O,15,0) -> 0 | X23: Milk Run | Y23: FIAPE | Z23: Não | AD23: 0.58333333 | AE23: 57879843000127 | AF23: 16701716003686 | AG23: Volume | AL23: =A23&B23&C23&AD23&AE23&AF23&O23&X23 -> FIAPEWEEK 018000066530,5833333333333335787984300012716701716003686SPMilk Run | AM23: =COUNTIF(PFEP!AW:AW,'Suppliers DB'!AL23) -> 15 | AN23: =COUNT(I23:N23) -> 1 | AO23: =COUNT(P23:U23) -> 1 | AP23: =IF(X23="",0,1) -> 1
A24: FIAPE | B24: WEEK 01 | C24: 800030982 | D24: CONTINENTAL KATHREIN-Jacutinga-MG | E24: R Wilson Silveira135Bl 3, 4, 5Vila Toledo | F24: Jacutinga | G24: MG | H24: Brasil | J24: =VLOOKUP(C24,'[10]Suppliers DB'!$A:$H,8,0) -> 0.2364 | O24: SP | Q24: =VLOOKUP(C24,'[10]Suppliers DB'!$A:$O,15,0) -> 50.22 | X24: Milk Run | Y24: FIAPE | Z24: Não | AD24: 0.625 | AE24: 60892528000578 | AF24: 16701716003686 | AG24: Volume | AL24: =A24&B24&C24&AD24&AE24&AF24&O24&X24 -> FIAPEWEEK 018000309820,6256089252800057816701716003686SPMilk Run | AM24: =COUNTIF(PFEP!AW:AW,'Suppliers DB'!AL101) -> 199 | AN24: =COUNT(I24:N24) -> 1 | AO24: =COUNT(P24:U24) -> 1 | AP24: =IF(X24="",0,1) -> 1
A25: FIAPE | B25: WEEK 01 | C25: 800005991 | D25: BOSAL II-Itupeva-SP | E25: Avenida Emilio Checchinato1928vila Sao Joao | F25: Itupeva | G25: SP | H25: Brasil | J25: =VLOOKUP(C25,'[10]Suppliers DB'!$A:$H,8,0) -> 0 | O25: SP | Q25: =VLOOKUP(C25,'[10]Suppliers DB'!$A:$O,15,0) -> 0 | X25: Milk Run | Y25: FIAPE | Z25: Não | AD25: 0.54166667 | AE25: 56993868000194 | AF25: 16701716003686 | AG25: Volume | AL25: =A25&B25&C25&AD25&AE25&AF25&O25&X25 -> FIAPEWEEK 018000059910,5416666666666675699386800019416701716003686SPMilk Run | AM25: =COUNTIF(PFEP!AW:AW,'Suppliers DB'!AL25) -> 8 | AN25: =COUNT(I25:N25) -> 1 | AO25: =COUNT(P25:U25) -> 1 | AP25: =IF(X25="",0,1) -> 1
A26: FIAPE | B26: WEEK 01 | C26: 800004739 | D26: CAILLAU-Diadema-SP | E26: Avenida Fagundes De Oliveira538galp]o 26bvila Sao | F26: Diadema | G26: SP | H26: Brasil | J26: =VLOOKUP(C26,'[10]Suppliers DB'!$A:$H,8,0) -> 0 | O26: SP | Q26: =VLOOKUP(C26,'[10]Suppliers DB'!$A:$O,15,0) -> 0 | W26: Toco ou veículos menores | X26: Milk Run | Y26: FIAPE | Z26: Não | AD26: 0.375 | AE26: 3244643000250 | AF26: 16701716003686 | AG26: Volume | AL26: =A26&B26&C26&AD26&AE26&AF26&O26&X26 -> FIAPEWEEK 018000047390,375324464300025016701716003686SPMilk Run | AM26: =COUNTIF(PFEP!AW:AW,'Suppliers DB'!AL26) -> 5 | AN26: =COUNT(I26:N26) -> 1 | AO26: =COUNT(P26:U26) -> 1 | AP26: =IF(X26="",0,1) -> 1
A27: FIAPE | B27: WEEK 01 | C27: 800002735 | D27: CASCO-Indaiatuba-SP | E27: R TRES 399 | F27: Indaiatuba | G27: SP | H27: Brasil | J27: =VLOOKUP(C27,'[10]Suppliers DB'!$A:$H,8,0) -> 0 | O27: SP | Q27: =VLOOKUP(C27,'[10]Suppliers DB'!$A:$O,15,0) -> 0 | X27: Milk Run | Y27: FIAPE | Z27: Não | AD27: 0.375 | AE27: 2220927000162 | AF27: 16701716003686 | AG27: Volume | AL27: =A27&B27&C27&AD27&AE27&AF27&O27&X27 -> FIAPEWEEK 018000027350,375222092700016216701716003686SPMilk Run | AM27: =COUNTIF(PFEP!AW:AW,'Suppliers DB'!AL27) -> 3 | AN27: =COUNT(I27:N27) -> 1 | AO27: =COUNT(P27:U27) -> 1 | AP27: =IF(X27="",0,1) -> 1
A28: FIAPE | B28: WEEK 01 | C28: 800028290 | D28: CCL LABEL-Vinhedo-SP | E28: Rod. Miguel Melhado Camposkm 79sta Candida | F28: Vinhedo | G28: SP | H28: Brasil | J28: =VLOOKUP(C28,'[10]Suppliers DB'!$A:$H,8,0) -> 0 | O28: SP | Q28: =VLOOKUP(C28,'[10]Suppliers DB'!$A:$O,15,0) -> 0 | X28: Milk Run | Y28: FIAPE | Z28: Não | AD28: 0.75 | AE28: 7593518000125 | AF28: 16701716003686 | AG28: Volume | AL28: =A28&B28&C28&AD28&AE28&AF28&O28&X28 -> FIAPEWEEK 018000282900,75759351800012516701716003686SPMilk Run | AM28: =COUNTIF(PFEP!AW:AW,'Suppliers DB'!AL28) -> 68 | AN28: =COUNT(I28:N28) -> 1 | AO28: =COUNT(P28:U28) -> 1 | AP28: =IF(X28="",0,1) -> 1
A29: FIAPE | B29: WEEK 01 | C29: 800036757 | D29: BORKAR-Itapecerica da Serra-SP | E29: R DAS NOGUEIRAS 398, ANTIGO N06 | F29: Itapecerica da Serra | G29: SP | H29: Brasil | J29: =VLOOKUP(C29,'[10]Suppliers DB'!$A:$H,8,0) -> 0.9456 | O29: SP | Q29: =VLOOKUP(C29,'[10]Suppliers DB'!$A:$O,15,0) -> 249.12 | X29: Milk Run | Y29: FIAPE | Z29: Não | AD29: 0.60416667 | AE29: 12475660000108 | AF29: 16701716003686 | AG29: Volume | AL29: =A29&B29&C29&AD29&AE29&AF29&O29&X29 -> FIAPEWEEK 018000367570,6041666666666671247566000010816701716003686SPMilk Run | AM29: =COUNTIF(PFEP!AW:AW,'Suppliers DB'!AL24) -> 4 | AN29: =COUNT(I29:N29) -> 1 | AO29: =COUNT(P29:U29) -> 1 | AP29: =IF(X29="",0,1) -> 1
A30: FIAPE | B30: WEEK 01 | C30: 800030246 | D30: CEQUENT-Itaquaquecetuba-SP | E30: Rua Flor de Noiva, 800 | F30: Itaquaquecetuba | G30: SP | H30: Brasil | J30: =VLOOKUP(C30,'[10]Suppliers DB'!$A:$H,8,0) -> 0 | O30: SP | Q30: =VLOOKUP(C30,'[10]Suppliers DB'!$A:$O,15,0) -> 0 | X30: Milk Run | Y30: FIAPE | Z30: Não | AD30: 0.54166667 | AE30: 1859648000261 | AF30: 16701716003686 | AG30: Volume | AL30: =A30&B30&C30&AD30&AE30&AF30&O30&X30 -> FIAPEWEEK 018000302460,541666666666667185964800026116701716003686SPMilk Run | AM30: =COUNTIF(PFEP!AW:AW,'Suppliers DB'!AL30) -> 1 | AN30: =COUNT(I30:N30) -> 1 | AO30: =COUNT(P30:U30) -> 1 | AP30: =IF(X30="",0,1) -> 1
A31: FIAPE | B31: WEEK 01 | C31: 800006273 | D31: CERAMICA E VELAS NGK-Mogi Das Cruzes-SP | E31: Rod. Prof. Alfredo Rolim De Mouras/nkm 61cocuera | F31: Mogi Das Cruzes | G31: SP | H31: Brasil | J31: =VLOOKUP(C31,'[10]Suppliers DB'!$A:$H,8,0) -> 0 | O31: SP | Q31: =VLOOKUP(C31,'[10]Suppliers DB'!$A:$O,15,0) -> 0 | X31: Milk Run | Y31: FIAPE | Z31: Não | AD31: 0.54166667 | AE31: 52541760000100 | AF31: 16701716003686 | AG31: Volume | AL31: =A31&B31&C31&AD31&AE31&AF31&O31&X31 -> FIAPEWEEK 018000062730,5416666666666675254176000010016701716003686SPMilk Run | AM31: =COUNTIF(PFEP!AW:AW,'Suppliers DB'!AL31) -> 9 | AN31: =COUNT(I31:N31) -> 1 | AO31: =COUNT(P31:U31) -> 1 | AP31: =IF(X31="",0,1) -> 1
A32: FIAPE | B32: WEEK 01 | C32: 800005765 | D32: COBRA METAIS-Itu-SP | E32: Av Tiradentes1806parque Industrial | F32: Itu | G32: SP | H32: Brasil | J32: =VLOOKUP(C32,'[10]Suppliers DB'!$A:$H,8,0) -> 0 | O32: SP | Q32: =VLOOKUP(C32,'[10]Suppliers DB'!$A:$O,15,0) -> 0 | W32: Não recebe carreta | X32: Milk Run | Y32: FIAPE | Z32: Não | AD32: 0.45833333 | AE32: 50231778000180 | AF32: 16701716003686 | AG32: Volume | AL32: =A32&B32&C32&AD32&AE32&AF32&O32&X32 -> FIAPEWEEK 018000057650,4583333333333335023177800018016701716003686SPMilk Run | AM32: =COUNTIF(PFEP!AW:AW,'Suppliers DB'!AL32) -> 10 | AN32: =COUNT(I32:N32) -> 1 | AO32: =COUNT(P32:U32) -> 1 | AP32: =IF(X32="",0,1) -> 1
A33: FIAPE | B33: WEEK 01 | C33: 800027618 | D33: COMPONENT INDUS-Diadema-SP | E33: Ferraz Alvim, 298 | F33: Diadema | G33: SP | H33: Brasil | J33: =VLOOKUP(C33,'[10]Suppliers DB'!$A:$H,8,0) -> 0 | O33: SP | Q33: =VLOOKUP(C33,'[10]Suppliers DB'!$A:$O,15,0) -> 0 | X33: Milk Run | Y33: FIAPE | Z33: Não | AD33: 0.54166667 | AE33: 62672415000169 | AF33: 16701716003686 | AG33: Volume | AL33: =A33&B33&C33&AD33&AE33&AF33&O33&X33 -> FIAPEWEEK 018000276180,5416666666666676267241500016916701716003686SPMilk Run | AM33: =COUNTIF(PFEP!AW:AW,'Suppliers DB'!AL33) -> 7 | AN33: =COUNT(I33:N33) -> 1 | AO33: =COUNT(P33:U33) -> 1 | AP33: =IF(X33="",0,1) -> 1
A34: FIAPE | B34: WEEK 01 | C34: 800006042 | D34: CONTINENTAL II-Guarulhos-SP | E34: Av Senador Adolf Schindling131vila Endres | F34: Guarulhos | G34: SP | H34: Brasil | J34: =VLOOKUP(C34,'[10]Suppliers DB'!$A:$H,8,0) -> 0 | O34: SP | Q34: =VLOOKUP(C34,'[10]Suppliers DB'!$A:$O,15,0) -> 0 | W34: Não recebe carreta | Apenas Veículos do tipo Sider | X34: Milk Run | Y34: FIAPE | Z34: Não | AD34: 0.79166667 | AE34: 48754139000157 | AF34: 16701716003686 | AG34: Volume | AL34: =A34&B34&C34&AD34&AE34&AF34&O34&X34 -> FIAPEWEEK 018000060420,7916666666666674875413900015716701716003686SPMilk Run | AM34: =COUNTIF(PFEP!AW:AW,'Suppliers DB'!AL34) -> 4 | AN34: =COUNT(I34:N34) -> 1 | AO34: =COUNT(P34:U34) -> 1 | AP34: =IF(X34="",0,1) -> 1
